/home/muugii/ca_prediction/venv/local/lib/python2.7/site-packages/requests/packages/urllib3/util/ssl_.py:315: SNIMissingWarning: An HTTPS request has been made, but the SNI (Subject Name Indication) extension to TLS is not available on this platform. This may cause the server to present an incorrect TLS certificate, which can cause validation failures. For more information, see https://urllib3.readthedocs.org/en/latest/security.html#snimissingwarning.
  SNIMissingWarning
/home/muugii/ca_prediction/venv/local/lib/python2.7/site-packages/requests/packages/urllib3/util/ssl_.py:120: InsecurePlatformWarning: A true SSLContext object is not available. This prevents urllib3 from configuring SSL appropriately and may cause certain SSL connections to fail. For more information, see https://urllib3.readthedocs.org/en/latest/security.html#insecureplatformwarning.
  InsecurePlatformWarning
/home/muugii/ca_prediction/venv/local/lib/python2.7/site-packages/requests/packages/urllib3/util/ssl_.py:120: InsecurePlatformWarning: A true SSLContext object is not available. This prevents urllib3 from configuring SSL appropriately and may cause certain SSL connections to fail. For more information, see https://urllib3.readthedocs.org/en/latest/security.html#insecureplatformwarning.
  InsecurePlatformWarning
/home/muugii/ca_prediction/venv/local/lib/python2.7/site-packages/requests/packages/urllib3/util/ssl_.py:120: InsecurePlatformWarning: A true SSLContext object is not available. This prevents urllib3 from configuring SSL appropriately and may cause certain SSL connections to fail. For more information, see https://urllib3.readthedocs.org/en/latest/security.html#insecureplatformwarning.
  InsecurePlatformWarning
/home/muugii/ca_prediction/venv/local/lib/python2.7/site-packages/requests/packages/urllib3/util/ssl_.py:120: InsecurePlatformWarning: A true SSLContext object is not available. This prevents urllib3 from configuring SSL appropriately and may cause certain SSL connections to fail. For more information, see https://urllib3.readthedocs.org/en/latest/security.html#insecureplatformwarning.
  InsecurePlatformWarning
Traceback (most recent call last):
  File "/home/muugii/ca_prediction/scripts/twitter/ca_author.py", line 117, in <module>
    main()
  File "/home/muugii/ca_prediction/scripts/twitter/ca_author.py", line 112, in main
    get_tweets(sys.argv[1])
  File "/home/muugii/ca_prediction/scripts/twitter/ca_author.py", line 83, in get_tweets
    perform((token_num + 1) % len(access_tokens), clan_name, user_id)
  File "/home/muugii/ca_prediction/scripts/twitter/ca_author.py", line 91, in perform
    get_tweet(token_num, user, clan_name)
  File "/home/muugii/ca_prediction/scripts/twitter/ca_author.py", line 107, in get_tweet
    for tweet in ts.search_tweets_iterable(tso):
  File "/home/muugii/ca_prediction/venv/local/lib/python2.7/site-packages/TwitterSearch/TwitterSearch.py", line 204, in search_tweets_iterable
    self.search_tweets(order)
  File "/home/muugii/ca_prediction/venv/local/lib/python2.7/site-packages/TwitterSearch/TwitterSearch.py", line 306, in search_tweets
    self.send_search(self._start_url)
  File "/home/muugii/ca_prediction/venv/local/lib/python2.7/site-packages/TwitterSearch/TwitterSearch.py", line 246, in send_search
    self.check_http_status(r.status_code)
  File "/home/muugii/ca_prediction/venv/local/lib/python2.7/site-packages/TwitterSearch/TwitterSearch.py", line 185, in check_http_status
    self.exceptions[http_status])
TwitterSearch.TwitterSearchException.TwitterSearchException: Error 404: ('Not Found: The URI requested is invalid or', 'the resource requested does not exists')
